Running `python manage.py syncdb` attached to terminal... up, run.9407
/app/.heroku/python/lib/python2.7/site-packages/django/core/management/commands/syncdb.py:24: RemovedInDjango19Warning: The syncdb command will be removed in Django 1.9
  warnings.warn("The syncdb command will be removed in Django 1.9", RemovedInDjango19Warning)

Operations to perform:
  Synchronize unmigrated apps: staticfiles, rest_framework, imdb, messages
  Apply all migrations: auth, contenttypes, admin, sites, sessions
Synchronizing apps without migrations:
  Creating tables...
    Creating table Genre
Traceback (most recent call last):
  File "manage.py", line 10, in <module>
    execute_from_command_line(sys.argv)
  File "/app/.heroku/python/lib/python2.7/site-packages/django/core/management/__init__.py", line 338, in execute_from_command_line
    utility.execute()
  File "/app/.heroku/python/lib/python2.7/site-packages/django/core/management/__init__.py", line 330, in execute
    self.fetch_command(subcommand).run_from_argv(self.argv)
  File "/app/.heroku/python/lib/python2.7/site-packages/django/core/management/base.py", line 390, in run_from_argv
    self.execute(*args, **cmd_options)
  File "/app/.heroku/python/lib/python2.7/site-packages/django/core/management/base.py", line 441, in execute
    output = self.handle(*args, **options)
  File "/app/.heroku/python/lib/python2.7/site-packages/django/core/management/commands/syncdb.py", line 25, in handle
    call_command("migrate", **options)
  File "/app/.heroku/python/lib/python2.7/site-packages/django/core/management/__init__.py", line 120, in call_command
    return command.execute(*args, **defaults)
  File "/app/.heroku/python/lib/python2.7/site-packages/django/core/management/base.py", line 441, in execute
    output = self.handle(*args, **options)
  File "/app/.heroku/python/lib/python2.7/site-packages/django/core/management/commands/migrate.py", line 179, in handle
    created_models = self.sync_apps(connection, executor.loader.unmigrated_apps)
  File "/app/.heroku/python/lib/python2.7/site-packages/django/core/management/commands/migrate.py", line 309, in sync_apps
    editor.create_model(model)
  File "/app/.heroku/python/lib/python2.7/site-packages/django/db/backends/base/schema.py", line 286, in create_model
    self.execute(sql, params or None)
  File "/app/.heroku/python/lib/python2.7/site-packages/django/db/backends/base/schema.py", line 111, in execute
    cursor.execute(sql, params)
  File "/app/.heroku/python/lib/python2.7/site-packages/django/db/backends/utils.py", line 79, in execute
    return super(CursorDebugWrapper, self).execute(sql, params)
  File "/app/.heroku/python/lib/python2.7/site-packages/django/db/backends/utils.py", line 64, in execute
    return self.cursor.execute(sql, params)
  File "/app/.heroku/python/lib/python2.7/site-packages/django/db/utils.py", line 97, in __exit__
    six.reraise(dj_exc_type, dj_exc_value, traceback)
  File "/app/.heroku/python/lib/python2.7/site-packages/django/db/backends/utils.py", line 62, in execute
    return self.cursor.execute(sql)
  File "/app/.heroku/python/lib/python2.7/site-packages/django/db/backends/mysql/base.py", line 124, in execute
    return self.cursor.execute(query, args)
  File "/app/.heroku/python/lib/python2.7/site-packages/pymysql/cursors.py", line 134, in execute
    result = self._query(query)
  File "/app/.heroku/python/lib/python2.7/site-packages/pymysql/cursors.py", line 282, in _query
    conn.query(q)
  File "/app/.heroku/python/lib/python2.7/site-packages/pymysql/connections.py", line 768, in query
    self._affected_rows = self._read_query_result(unbuffered=unbuffered)
  File "/app/.heroku/python/lib/python2.7/site-packages/pymysql/connections.py", line 929, in _read_query_result
    result.read()
  File "/app/.heroku/python/lib/python2.7/site-packages/pymysql/connections.py", line 1125, in read
    first_packet = self.connection._read_packet()
  File "/app/.heroku/python/lib/python2.7/site-packages/pymysql/connections.py", line 893, in _read_packet
    packet.check_error()
  File "/app/.heroku/python/lib/python2.7/site-packages/pymysql/connections.py", line 369, in check_error
    err.raise_mysql_exception(self._data)
  File "/app/.heroku/python/lib/python2.7/site-packages/pymysql/err.py", line 120, in raise_mysql_exception
    _check_mysql_exception(errinfo)
  File "/app/.heroku/python/lib/python2.7/site-packages/pymysql/err.py", line 115, in _check_mysql_exception
    raise InternalError(errno, errorvalue)
django.db.utils.InternalError: (1050, u"Table 'genre' already exists")
